Workbook

Sheet Plantilla de Casos de Prueba
A1: Plantilla de Casos de Pruebas de Software
A2: Proyecto: BarbershopMya
A3: Ciclo de Pruebas: Ciclo 1 - Pruebas unitarias (caja blanca) y de sistema (caja negra) por módulo
L4: Información para el Seguimiento
A5: Id | B5: Caso de Prueba | C5: Descripción | D5: Fecha | E5: Área Funcional / Sub proceso | F5: Funcionalidad / Característica | G5: Datos / Acciones de Entrada | H5: Resultado Esperado | I5: Requerimientos de Ambiente de Pruebas | J5: Procedimientos especiales requeridos | K5: Dependencias con otros casos de Prueba | L5: Resultado Obtenido* | M5: Estado | N5: Última Fecha de Estado | O5: Observaciones
A6: USR-01 | B6: Caja negra | Registro con datos válidos | C6: Técnica: Partición equivalente. Clase válida: todos los campos correctos. | D6: 46309 | E6: Usuarios | F6: Registro de usuario | G6: Nombre: Carlos Pérez Correo: carlos@mail.com Clave: Barber2026* Teléfono: 3001234567 Acción: clic en Registrarse | H6: Usuario creado en BD, mensaje de éxito y redirección al login. | I6: Chrome + servidor local (runserver) + MySQL con datos semilla | J6: Ninguno | K6: Ninguna | L6: #VALUE! | M6: Aprobada | N6: 46309 | O6: El registro fue exitoso
A7: USR-02 | B7: Caja negra | Registro con correo sin @ | C7: Técnica: Partición equivalente. Clase inválida: formato de correo incorrecto. | D7: 46309 | E7: Usuarios | F7: Registro de usuario | G7: Correo: carlosmail.com Demás campos válidos | H7: Se rechaza el registro y se muestra 'correo inválido'. No se crea usuario. | I7: Chrome + servidor local (runserver) + MySQL con datos semilla | J7: Ninguno | K7: Ninguna | L7: #VALUE! | M7: Aprobada | N7: 46309 | O7: El input pide la @ para poder registrar al usuario
A8: USR-03 | B8: Caja negra | Registro con correo ya registrado | C8: Técnica: Partición equivalente. Clase inválida: correo duplicado. | D8: 46309 | E8: Usuarios | F8: Registro de usuario | G8: Correo: carlos@mail.com (ya existe) Demás campos válidos | H8: Se rechaza con mensaje 'correo ya registrado'. No se duplica el usuario. | I8: Chrome + servidor local (runserver) + MySQL con datos semilla | J8: Ninguno | K8: USR-01 | M8: Aprobada | N8: 46309 | O8: No autoriza el registro con un correo ya existente registrado
A9: USR-04 | B9: Caja negra | Clave de 7 caracteres (bajo el mínimo) | C9: Técnica: Valores límite. Límite inferior - 1. | D9: 46309 | E9: Usuarios | F9: Registro de usuario | G9: Clave: Barb26* (7 caracteres) Demás campos válidos | H9: Se rechaza: la clave debe tener mínimo 8 caracteres. | I9: Chrome + servidor local (runserver) + MySQL con datos semilla | J9: Ninguno | K9: Ninguna | L9: #VALUE! | M9: Aprobada | N9: 46309 | O9: La clave no permite por seguridad el ingreso de contraseñas bajo el minimo
A10: USR-05 | B10: Caja negra | Clave de 8 caracteres (límite mínimo) | C10: Técnica: Valores límite. Límite inferior exacto. | D10: 46309 | E10: Usuarios | F10: Registro de usuario | G10: Clave: Barber26 (8 caracteres) Correo: ana@mail.com Demás campos válidos | H10: Registro exitoso. | I10: Chrome + servidor local (runserver) + MySQL con datos semilla | J10: Ninguno | K10: Ninguna | L10: #VALUE! | M10: Aprobada | N10: 46309 | O10: Registro exitoso
A11: USR-06 | B11: Caja negra | Clave de 33 caracteres (sobre el máximo) | C11: Técnica: Valores límite. Límite superior + 1. | D11: 46309 | E11: Usuarios | F11: Registro de usuario | G11: Clave: 'Ab1' + 30 veces 'a' (33 caracteres) Demás campos válidos | H11: Se rechaza: la clave admite máximo 32 caracteres. | I11: Chrome + servidor local (runserver) + MySQL con datos semilla | J11: Ninguno | K11: Ninguna | L11: #VALUE! | M11: En espera | N11: 46309 | O11: No se ha establecido un limite de caracteres en la contraseña
A12: USR-07 | B12: Caja negra | Teléfono con letras | C12: Técnica: Partición equivalente. Clase inválida: no numérico. | D12: 46309 | E12: Usuarios | F12: Registro de usuario | G12: Teléfono: 300abc4567 Demás campos válidos | H12: Se rechaza con mensaje 'el teléfono solo debe contener números'. | I12: Chrome + servidor local (runserver) + MySQL con datos semilla | J12: Ninguno | K12: Ninguna | L12: #VALUE! | M12: Aprobada | N12: 46309 | O12: El input no permite ingresar letras en el telefono
A13: USR-08 | B13: Caja negra | Teléfono de 9 y de 11 dígitos | C13: Técnica: Valores límite. Límites inválidos alrededor de los 10 dígitos. | D13: 46309 | E13: Usuarios | F13: Registro de usuario | G13: Prueba 1: 300123456 (9 dígitos) Prueba 2: 30012345678 (11 dígitos) | H13: Ambos se rechazan: el teléfono debe tener exactamente 10 dígitos. | I13: Chrome + servidor local (runserver) + MySQL con datos semilla | J13: Ninguno | K13: Ninguna | L13: #VALUE! | M13: Aprobada | N13: 46309 | O13: El input del telefono esta delimitado a una cantidad exacta de caracteres ingresables
A14: USR-09 | B14: Caja negra | Registro con campos obligatorios vacíos | C14: Técnica: Partición equivalente. Clase inválida: campos vacíos. | D14: 46309 | E14: Usuarios | F14: Registro de usuario | G14: Todos los campos vacíos Acción: clic en Registrarse | H14: Se muestran mensajes de campo obligatorio. No se crea usuario. | I14: Chrome + servidor local (runserver) + MySQL con datos semilla | J14: Ninguno | K14: Ninguna | L14: #VALUE! | M14: Aprobada | N14: 46309 | O14: El input del registro pide el ingreso de datos de manera obligatoria en estos campos
A15: USR-10 | B15: Caja negra | Inicio de sesión válido | C15: Técnica: Partición equivalente. Clase válida: credenciales correctas. | D15: 46309 | E15: Usuarios | F15: Inicio de sesión | G15: Correo: carlos@mail.com Clave: Barber2026* | H15: Acceso concedido y redirección al panel del usuario. | I15: Chrome + servidor local (runserver) + MySQL con datos semilla | J15: Ninguno | K15: USR-01 | L15: #VALUE! | M15: Aprobada | N15: 46309 | O15: Inicio de sesion exitoso
A16: USR-11 | B16: Caja negra | Inicio de sesión con clave incorrecta | C16: Técnica: Partición equivalente. Clase inválida: clave errónea. | D16: 46309 | E16: Usuarios | F16: Inicio de sesión | G16: Correo: carlos@mail.com Clave: Incorrecta1 | H16: Acceso denegado con mensaje genérico 'credenciales incorrectas'. | I16: Chrome + servidor local (runserver) + MySQL con datos semilla | J16: Ninguno | K16: USR-01 | L16: #VALUE! | M16: Aprobada | N16: 46309 | O16: El sistema no autoriza si la clave es diferente a la registrada
A17: USR-12 | B17: Caja negra | Acceso a página protegida sin sesión | C17: Técnica: Prueba de sistema. Se intenta abrir una URL privada sin autenticarse. | D17: 46309 | E17: Usuarios | F17: Control de acceso | G17: Abrir directamente la URL del panel de reservas sin iniciar sesión | H17: El sistema redirige al login. No se muestra información privada. | I17: Chrome + servidor local (runserver) + MySQL con datos semilla | J17: Ninguno | K17: Ninguna | L17: #VALUE! | M17: Aprobada | N17: 46309 | O17: No se autoriza el inicio a datos de otros usuarios o roles y retornara al inicio de sesion
A18: SRV-01 | B18: Caja negra | Crear servicio con datos válidos | C18: Técnica: Partición equivalente. Clase válida. | D18: 46309 | E18: Servicios | F18: Gestión de servicios | G18: Nombre: Corte clásico Precio: 25000 Duración: 30 min Rol: administrador | H18: Servicio creado y visible en el listado. | I18: Chrome + servidor local (runserver) + MySQL con datos semilla | J18: Iniciar sesión como administrador | K18: USR-10 | L18: #VALUE! | M18: Aprobada | N18: 46309 | O18: El servicio se creo exitosamente
A19: SRV-02 | B19: Caja negra | Precio igual a 0 | C19: Técnica: Valores límite. Límite: 0 es inválido, 1 es el mínimo válido. | D19: 46309 | E19: Servicios | F19: Gestión de servicios | G19: Precio: 0 Demás campos válidos | H19: Se rechaza: el precio debe ser mayor que 0. | I19: Chrome + servidor local (runserver) + MySQL con datos semilla | J19: Iniciar sesión como administrador | K19: USR-10 | L19: #VALUE! | M19: Fallida | N19: 46309 | O19: El sistema permite crear el servicio lo cual es un error con los inputs
A20: SRV-03 | B20: Caja negra | Precio negativo | C20: Técnica: Partición equivalente. Clase inválida. | D20: 46309 | E20: Servicios | F20: Gestión de servicios | G20: Precio: -5000 Demás campos válidos | H20: Se rechaza con mensaje de precio inválido. | I20: Chrome + servidor local (runserver) + MySQL con datos semilla | J20: Iniciar sesión como administrador | K20: USR-10 | L20: #VALUE! | M20: Fallida | N20: 46309 | O20: El sistema permite datos negativos lo cual es un error de inputs
... A31: NEG-04 | B31: Caja negra | Nombre del negocio vacío | C31: Técnica: Partición equivalente. Clase inválida. | D31: 46309 | E31: Negocio | F31: Perfil y agenda del negocio | G31: Nombre: (vacío) Demás campos válidos | H31: Se rechaza con mensaje de campo obligatorio. | I31: Chrome + servidor local (runserver) + MySQL con datos semilla | J31: Iniciar sesión como administrador | K31: USR-10 | L31: #VALUE! | M31: En espera | N31: 46309 | O31: No hay una sección en donde el admin pueda cambiar el nombre a la barbería
A32: NEG-05 | B32: Caja negra | Editar datos y verificar persistencia | C32: Técnica: Prueba de sistema. Se modifica el teléfono y se recarga la página. | D32: 46309 | E32: Negocio | F32: Editar negocio | G32: Teléfono: cambiar a 3119876543 Acción: guardar y recargar (F5) | H32: El nuevo valor se mantiene tras recargar y está en MySQL. | I32: Chrome + servidor local (runserver) + MySQL con datos semilla | J32: Iniciar sesión como administrador | K32: NEG-01 | M32: Aprobada | N32: 46309 | O32: Los cambios que se realizan en el index desde el dashboard del admin se visualizan en el index exitosamente.
A33: NEG-06 | B33: Caja negra | Cliente intenta editar el negocio | C33: Técnica: Prueba de sistema. Control de permisos por rol. | D33: 46309 | E33: Negocio | F33: Control de acceso | G33: Sesión de cliente Acción: abrir URL de edición del negocio | H33: Acceso denegado (403) o redirección. No se permite editar. | I33: Chrome + servidor local (runserver) + MySQL con datos semilla | J33: No requiere sesión | K33: Ninguna | L33: #VALUE! | M33: Aprobada | N33: 46309 | O33: Si un cliente intenta modificar el index desde el panel del admin no se lo va a permitir.
A34: RES-01 | B34: Caja negra | Crear reserva válida | C34: Técnica: Partición equivalente. Clase válida. | D34: 46309 | E34: Reservas | F34: Crear y cancelar reserva | G34: Servicio: Corte clásico (30 min) Barbero: Juan Fecha: [fecha futura laborable] Hora: 10:00 | H34: Reserva creada con estado Confirmada y visible en 'Mis reservas'. | I34: Chrome + servidor local (runserver) + MySQL con datos semilla | J34: Iniciar sesión como cliente | K34: USR-10, SRV-01, NEG-01 | L34: #VALUE! | M34: Aprobada | N34: 46309 | O34: Permite crear la reserva exitosamente.
A35: RES-02 | B35: Caja negra | Reserva en fecha pasada | C35: Técnica: Partición equivalente. Clase inválida. | D35: 46309 | E35: Reservas | F35: Crear y cancelar reserva | G35: Fecha: ayer Hora: 10:00 Demás datos válidos | H35: Se rechaza: no se permiten fechas pasadas. | I35: Chrome + servidor local (runserver) + MySQL con datos semilla | J35: Iniciar sesión como cliente | K35: USR-10, SRV-01 | L35: #VALUE! | M35: Aprobada | N35: 46309 | O35: Si un cliente quiere reservar en fechas que ya han pasado no podrá ya que estan deshabilitadas y no las podrá seleccionar
A36: RES-03 | B36: Caja negra | Hora 07:59 (antes de la hora de inicio de la agenda) | C36: Técnica: Valores límite. Límite inferior - 1 minuto. | D36: 46309 | E36: Reservas | F36: Crear y cancelar reserva | G36: Fecha: [fecha futura laborable] Hora: 07:59 | H36: Se rechaza: fuera de la agenda del negocio. | I36: Chrome + servidor local (runserver) + MySQL con datos semilla | J36: Iniciar sesión como cliente | K36: NEG-01, SRV-01 | L36: #VALUE! | M36: Aprobada | N36: 46309 | O36: No puede iniciar sesión antes de las 8:00 a.m puesto que no esta dentro del range de horas que estan establecidas.
A37: RES-04 | B37: Caja negra | Hora 08:00 (hora de inicio de la agenda) | C37: Técnica: Valores límite. Límite inferior exacto. | D37: 46309 | E37: Reservas | F37: Crear y cancelar reserva | G37: Fecha: [fecha futura laborable] Hora: 08:00 | H37: Reserva creada correctamente. | I37: Chrome + servidor local (runserver) + MySQL con datos semilla | J37: Iniciar sesión como cliente | K37: NEG-01, SRV-01 | L37: #VALUE! | M37: Aprobada | N37: 46309 | O37: El cliente ya puede iniciar desde las 8:00 a.m.
A38: RES-05 | B38: Caja negra | Cita que termina pasada la hora fin de la agenda | C38: Técnica: Valores límite. Servicio de 30 min con hora fin de agenda 19:00: 18:30 válida, 18:45 inválida. | D38: 46309 | E38: Reservas | F38: Crear y cancelar reserva | G38: Prueba 1: Hora 18:30 Prueba 2: Hora 18:45 Fecha: [fecha futura laborable] | H38: 18:30 se acepta; 18:45 se rechaza porque terminaría después de la hora fin de la agenda. | I38: Chrome + servidor local (runserver) + MySQL con datos semilla | J38: Iniciar sesión como cliente | K38: NEG-01, SRV-01 | L38: #VALUE! | M38: Aprobada | N38: 46309 | O38: Las horas ya esatn establecidas puesto que no puede reversar despues de la hora fin de la agenda de los barberos.
A39: RES-06 | B39: Caja negra | Doble reserva: mismo barbero y misma hora | C39: Técnica: Partición equivalente. Clase inválida: horario ocupado. | D39: 46309 | E39: Reservas | F39: Crear y cancelar reserva | G39: Barbero: Juan Fecha: [fecha futura laborable] Hora: 10:00 (ya reservada) | H39: Se rechaza con mensaje 'horario no disponible'. | I39: Chrome + servidor local (runserver) + MySQL con datos semilla | J39: Iniciar sesión con un segundo cliente | K39: RES-01 | L39: #VALUE! | M39: Aprobada | N39: 46309 | O39: Si otro cliente intenta reservar a la misma hora y con el mismo barbero el mismo día no podrá ya que ese cupo ya está ocupado con la reserva de otro cliente.
A40: RES-07 | B40: Caja negra | Reservas consecutivas sin traslape | C40: Técnica: Valores límite. Cita nueva inicia justo cuando termina la anterior. | D40: 46309 | E40: Reservas | F40: Crear y cancelar reserva | G40: Barbero: Juan Fecha: [fecha futura laborable] Hora: 10:30 (la anterior termina 10:30) | H40: Reserva creada: no hay traslape. | I40: Chrome + servidor local (runserver) + MySQL con datos semilla | J40: Iniciar sesión como cliente | K40: RES-01 | L40: #VALUE! | M40: Aprobada | N40: 46309 | O40: El cliente no puede reservar mas de una cita para el mismo día por lo que no van a ver problemas con las reservas de los demás clientes por si quieren reservar ese día tambien.
A41: RES-08 | B41: Caja negra | Reserva sin seleccionar servicio | C41: Técnica: Partición equivalente. Clase inválida: dato obligatorio vacío. | D41: 46309 | E41: Reservas | F41: Crear y cancelar reserva | G41: Servicio: (ninguno) Fecha: [fecha futura laborable] Hora: 11:00 | H41: Se rechaza con mensaje de campo obligatorio. | I41: Chrome + servidor local (runserver) + MySQL con datos semilla | J41: No requiere sesión | K41: Ninguna | L41: #VALUE! | M41: Aprobada | N41: 46309 | O41: No se puede crear una reserva sino se selecciona un servicio.
A42: RES-09 | B42: Caja negra | Cancelar reserva propia | C42: Técnica: Partición equivalente. Clase válida. | D42: 46309 | E42: Reservas | F42: Cancelar reserva | G42: Acción: cancelar la reserva de RES-01 | H42: Estado cambia a Cancelada y el horario queda disponible. | I42: Chrome + servidor local (runserver) + MySQL con datos semilla | J42: Iniciar sesión como el cliente dueño | K42: RES-01 | L42: #VALUE! | M42: Aprobada | N42: 46309 | O42: El cliente puede cancelar su cita exitosamente.
A43: RES-10 | B43: Caja negra | Cancelar reserva de otro cliente | C43: Técnica: Prueba de sistema. Control de acceso entre usuarios. | D43: 46309 | E43: Reservas | F43: Cancelar reserva | G43: Con otra sesión, abrir la URL de cancelación de una reserva ajena | H43: Acceso denegado (403/404). La reserva no cambia. | I43: Chrome + servidor local (runserver) + MySQL con datos semilla | J43: Iniciar sesión con un segundo cliente | K43: RES-01 | L43: #VALUE! | M43: Aprobada | N43: 46309 | O43: Si un cliente diferente intenta cancelar la cita de otro cliente copiando la URL no podrá y se mostrará la pantalla de Django
A44: RES-12 | B44: Caja negra | Flujo completo: registro, login, reserva y cancelación | C44: Técnica: Prueba de sistema. Recorrido extremo a extremo (ideal para automatizar con Playwright). | D44: 46309 | E44: Reservas | F44: Flujo principal del cliente | G44: 1. Registrarse 2. Iniciar sesión 3. Reservar corte 4. Ver 'Mis reservas' 5. Cancelar | H44: Cada paso se completa sin errores y los datos quedan consistentes en MySQL. | I44: Chrome + servidor local (runserver) + MySQL con datos semilla | J44: BD limpia con servicio y negocio configurados | K44: USR-01, USR-10, RES-01, RES-09 | M44: Aprobada | N44: 46309 | O44: El cliente puede hacer todo el flujo de reservación desde que se registra, inicia sesón, reserva una cita, visualiza el historial de sus citas y la cancelación de su reserva.
A45: FAC-01 | B45: Caja negra | Imagen JPG con un rostro nítido | C45: Técnica: Partición equivalente. Clase válida. | D45: 46309 | E45: Análisis facial | F45: Análisis de rostro y recomendación | G45: Archivo: rostro_frontal.jpg (2 MB, un solo rostro, buena luz) | H45: Se detecta el rostro, se muestra la forma facial y las recomendaciones de corte. | I45: Chrome + servidor local (runserver) + MySQL con datos semilla | J45: No requiere sesión; imágenes de prueba preparadas | K45: Ninguna | L45: #VALUE! | M45: Aprobada | N45: 46309 | O45: Se realiza el análisis facial exitosamente.
A46: FAC-02 | B46: Caja negra | Imagen PNG válida | C46: Técnica: Partición equivalente. Clase válida: otro formato permitido. | D46: 46309 | E46: Análisis facial | F46: Análisis de rostro y recomendación | G46: Archivo: rostro_frontal.png (1 MB) | H46: Se procesa y se muestra el resultado igual que con JPG. | I46: Chrome + servidor local (runserver) + MySQL con datos semilla | J46: No requiere sesión | K46: Ninguna | L46: #VALUE! | M46: Aprobada | N46: 46309 | O46: Al hacer el análsiis facial completo permite ver las recomendaciones de corte de acuerdo a su tipo de rostro.
A47: FAC-03 | B47: Caja negra | Formato de archivo no permitido | C47: Técnica: Partición equivalente. Clase inválida: PDF y GIF. | D47: 46309 | E47: Análisis facial | F47: Análisis de rostro y recomendación | G47: Prueba 1: documento.pdf Prueba 2: animacion.gif | H47: Se rechazan con mensaje de formato no permitido (solo JPG/PNG). | I47: Chrome + servidor local (runserver) + MySQL con datos semilla | J47: No requiere sesión | K47: Ninguna | L47: #VALUE! | M47: Aprobada | N47: 46309 | O47: Si usuario quiere subir un archivo en PDF, WORD o GIF no los podrá encontrar en sus archivos debido a que no se permite este tipo de archivos para el análisis.
A48: FAC-04 | B48: Caja negra | Imagen de exactamente 5 MB | C48: Técnica: Valores límite. Límite máximo exacto. | D48: 46309 | E48: Análisis facial | F48: Análisis de rostro y recomendación | G48: Archivo: rostro_5mb.jpg (5 242 880 bytes) | H48: Se acepta y procesa correctamente. | I48: Chrome + servidor local (runserver) + MySQL con datos semilla | J48: No requiere sesión | K48: Ninguna | M48: Aprobada | N48: 46309 | O48: Si permite imágenes de 5 MB.
A49: FAC-05 | B49: Caja negra | Imagen de 5,1 MB | C49: Técnica: Valores límite. Límite máximo + 1. | D49: 46309 | E49: Análisis facial | F49: Análisis de rostro y recomendación | G49: Archivo: rostro_51mb.jpg | H49: Se rechaza: tamaño máximo 5 MB. | I49: Chrome + servidor local (runserver) + MySQL con datos semilla | J49: No requiere sesión | K49: Ninguna | L49: #VALUE! | M49: Aprobada | N49: 46309 | O49: Si el usuario tiene una imagen mayor de 5 MB no le apareceran en los archivos para hacer el análisis facial.
A50: FAC-06 | B50: Caja negra | Imagen sin rostro | C50: Técnica: Partición equivalente. Clase inválida: sin rostro detectable. | D50: 46309 | E50: Análisis facial | F50: Análisis de rostro y recomendación | G50: Archivo: paisaje.jpg | H50: Mensaje 'no se detectó ningún rostro'. No se generan recomendaciones. | I50: Chrome + servidor local (runserver) + MySQL con datos semilla | J50: No requiere sesión | K50: Ninguna | L50: #VALUE! | M50: Aprobada | N50: 46309 | O50: Al tomar la foto con la cámara si no detecta un rostro le aparece un mensaje donde se le dira que no detecta ningún rostro.
...

Sheet Instrucciones
A1: ='Plantilla de Casos de Prueba'!A1 -> Plantilla de Casos de Pruebas de Software
A2: Elaborado por: www.pmoinformatica.com
A4: Descripción de la información a completar en cada columna
A5: Columna | B5: Instrucciones
A6: ='Plantilla de Casos de Prueba'!A5 -> Id | B6: Cada caso de prueba debe tener un identificador (código) único.
A7: ='Plantilla de Casos de Prueba'!B5 -> Caso de Prueba | B7: Título descriptivo del caso de prueba.
A8: ='Plantilla de Casos de Prueba'!C5 -> Descripción | B8: Descripción del caso de prueba, indicando sus elementos, funcionalidades y acciones a ser ejercidas en el caso de prueba.
A9: ='Plantilla de Casos de Prueba'!D5 -> Fecha | B9: Fecha en que fue creado el caso de prueba.
A10: ='Plantilla de Casos de Prueba'!E5 -> Área Funcional / Sub proceso | B10: Describe el área funcional, subproceso o modulo al que está asociado el caso de prueba. La intención es poder dividir los casos de prueba según la estructura jerárquica funcional del sistema que se está probando y los procesos que este soporta.
A11: ='Plantilla de Casos de Prueba'!F5 -> Funcionalidad / Característica | B11: Describe el título de la característica o funcionalidad que se está probando. Por ej. Suscripción al Servicio, Entrega de Orden, Selección de Producto, Consulta de Ordenes Pendientes.
A12: ='Plantilla de Casos de Prueba'!G5 -> Datos / Acciones de Entrada | B12: Se especifica cada entrada que se requiere para ejecutar el caso de prueba. Etas entradas pueden ser valores o datos de entrada, y también acciones (por ejemplo presionar un botón). Deben identificarse los archivos o bases de datos involucrados.
A13: ='Plantilla de Casos de Prueba'!H5 -> Resultado Esperado | B13: Se especifica la salida que se espera de la ejecución de los casos de prueba con las entradas indicadas.
A14: ='Plantilla de Casos de Prueba'!I5 -> Requerimientos de Ambiente de Pruebas | B14: Cualquier especificación del hardware y software especial requerido para ejecutar el caso de prueba, que no sea común a todos los casos. Las que sean comunes a todos los casos se deben especificar en la sección de Entornos del Plan de Pruebas de Software.
A15: ='Plantilla de Casos de Prueba'!J5 -> Procedimientos especiales requeridos | B15: Se describen cualquier restricción o condicionamiento en los procedimientos de prueba asociados a cada caso.
A16: ='Plantilla de Casos de Prueba'!K5 -> Dependencias con otros casos de Prueba | B16: Lista de los identificadores de los casos de prueba que deben ejecutarse antes de este caso. También puede incluir un sumario de la naturaleza de estas dependencias.
A17: Información para el seguimiento
A18: ='Plantilla de Casos de Prueba'!L5 -> Resultado Obtenido* | B18: Se describe el resultado real obtenido de la ejecución del caso de prueba (Este es una columna de seguimiento). Si esta difiere del resultado esperado, debería especificarse en un reporte de incidencia.
A19: ='Plantilla de Casos de Prueba'!M5 -> Estado | B19: Estado actual del caso de prueba.
A20: ='Plantilla de Casos de Prueba'!N5 -> Última Fecha de Estado | B20: Última fecha en que se ejecutó una acción referente al caso o que este cambio de estado.
A21: ='Plantilla de Casos de Prueba'!O5 -> Observaciones | B21: Observaciones relacionadas con la ejecución de los casos y de los resultados que se obtuvieron.

Sheet Resumen y supuestos
A1: Resumen del ciclo de pruebas - BarbershopMya
A3: Módulo | B3: Total casos | C3: Aprobada | D3: Fallida | E3: En espera | F3: Sin ejecutar
A4: Usuarios | B4: =COUNTIF('Plantilla de Casos de Prueba'!$E$6:$E$197,A4) -> 12 | C4: =COUNTIFS('Plantilla de Casos de Prueba'!$E$6:$E$197,$A4,'Plantilla de Casos de Prueba'!$M$6:$M$197,"Aprobada") -> 11 | D4: =COUNTIFS('Plantilla de Casos de Prueba'!$E$6:$E$197,$A4,'Plantilla de Casos de Prueba'!$M$6:$M$197,"Fallida") -> 0 | E4: =COUNTIFS('Plantilla de Casos de Prueba'!$E$6:$E$197,$A4,'Plantilla de Casos de Prueba'!$M$6:$M$197,"En espera") -> 1 | F4: =COUNTIFS('Plantilla de Casos de Prueba'!$E$6:$E$197,$A4,'Plantilla de Casos de Prueba'!$M$6:$M$197,"Sin ejecutar") -> 0
A5: Servicios | B5: =COUNTIF('Plantilla de Casos de Prueba'!$E$6:$E$197,A5) -> 10 | C5: =COUNTIFS('Plantilla de Casos de Prueba'!$E$6:$E$197,$A5,'Plantilla de Casos de Prueba'!$M$6:$M$197,"Aprobada") -> 6 | D5: =COUNTIFS('Plantilla de Casos de Prueba'!$E$6:$E$197,$A5,'Plantilla de Casos de Prueba'!$M$6:$M$197,"Fallida") -> 4 | E5: =COUNTIFS('Plantilla de Casos de Prueba'!$E$6:$E$197,$A5,'Plantilla de Casos de Prueba'!$M$6:$M$197,"En espera") -> 0 | F5: =COUNTIFS('Plantilla de Casos de Prueba'!$E$6:$E$197,$A5,'Plantilla de Casos de Prueba'!$M$6:$M$197,"Sin ejecutar") -> 0
A6: Negocio | B6: =COUNTIF('Plantilla de Casos de Prueba'!$E$6:$E$197,A6) -> 6 | C6: =COUNTIFS('Plantilla de Casos de Prueba'!$E$6:$E$197,$A6,'Plantilla de Casos de Prueba'!$M$6:$M$197,"Aprobada") -> 2 | D6: =COUNTIFS('Plantilla de Casos de Prueba'!$E$6:$E$197,$A6,'Plantilla de Casos de Prueba'!$M$6:$M$197,"Fallida") -> 3 | E6: =COUNTIFS('Plantilla de Casos de Prueba'!$E$6:$E$197,$A6,'Plantilla de Casos de Prueba'!$M$6:$M$197,"En espera") -> 1 | F6: =COUNTIFS('Plantilla de Casos de Prueba'!$E$6:$E$197,$A6,'Plantilla de Casos de Prueba'!$M$6:$M$197,"Sin ejecutar") -> 0
A7: Reservas | B7: =COUNTIF('Plantilla de Casos de Prueba'!$E$6:$E$197,A7) -> 11 | C7: =COUNTIFS('Plantilla de Casos de Prueba'!$E$6:$E$197,$A7,'Plantilla de Casos de Prueba'!$M$6:$M$197,"Aprobada") -> 11 | D7: =COUNTIFS('Plantilla de Casos de Prueba'!$E$6:$E$197,$A7,'Plantilla de Casos de Prueba'!$M$6:$M$197,"Fallida") -> 0 | E7: =COUNTIFS('Plantilla de Casos de Prueba'!$E$6:$E$197,$A7,'Plantilla de Casos de Prueba'!$M$6:$M$197,"En espera") -> 0 | F7: =COUNTIFS('Plantilla de Casos de Prueba'!$E$6:$E$197,$A7,'Plantilla de Casos de Prueba'!$M$6:$M$197,"Sin ejecutar") -> 0
A8: Análisis facial | B8: =COUNTIF('Plantilla de Casos de Prueba'!$E$6:$E$197,A8) -> 12 | C8: =COUNTIFS('Plantilla de Casos de Prueba'!$E$6:$E$197,$A8,'Plantilla de Casos de Prueba'!$M$6:$M$197,"Aprobada") -> 11 | D8: =COUNTIFS('Plantilla de Casos de Prueba'!$E$6:$E$197,$A8,'Plantilla de Casos de Prueba'!$M$6:$M$197,"Fallida") -> 1 | E8: =COUNTIFS('Plantilla de Casos de Prueba'!$E$6:$E$197,$A8,'Plantilla de Casos de Prueba'!$M$6:$M$197,"En espera") -> 0 | F8: =COUNTIFS('Plantilla de Casos de Prueba'!$E$6:$E$197,$A8,'Plantilla de Casos de Prueba'!$M$6:$M$197,"Sin ejecutar") -> 0
A9: Total | B9: =SUM(B4:B8) -> 51 | C9: =SUM(C4:C8) -> 41 | D9: =SUM(D4:D8) -> 8 | E9: =SUM(E4:E8) -> 2 | F9: =SUM(F4:F8) -> 0
A12: Supuestos (ajustar a las reglas reales del sistema)
A13: 1. Clave: de 8 a 32 caracteres, con al menos una letra y un número.
A14: 2. Teléfono: exactamente 10 dígitos numéricos (formato colombiano).
A15: 3. Precio del servicio: mayor que 0. Duración: de 15 a 180 minutos. Los servicios se eliminan (no se inactivan); un servicio con reservas no se puede eliminar.
A16: 4. Agenda del negocio de ejemplo: hora inicio 08:00 y hora fin 19:00. La hora fin debe ser posterior a la hora inicio.
A17: 5. Una reserva no puede traslaparse con otra del mismo barbero; no se permiten fechas pasadas ni citas que terminen después de la hora fin de la agenda.
A18: 6. Análisis facial: de uso libre, sin iniciar sesión. Acepta JPG y PNG de hasta 5 MB, con un solo rostro; respuesta en 10 s o menos.
A19: 7. Roles: administrador (gestiona servicios y negocio) y cliente (reserva). El análisis facial no requiere rol.
A20: 8. Los nombres de datos (Carlos Pérez, Juan, Corte clásico) son de ejemplo; reemplazar por los datos reales de prueba.
A21: 9. Los casos de caja blanca (USR-13, RES-11) suponen funciones de validación independientes que se puedan probar con Django TestCase o pytest.
A22: 10. Todos los casos quedan en estado 'Sin ejecutar'; Resultado Obtenido, Última Fecha de Estado y Observaciones se llenan al ejecutarlos.
